<?xml version="1.0" ?>
<!-- =================================================================================== -->
<!-- |    This document was autogenerated by xacro from aubo_i5.xacro                  | -->
<!-- |    EDITING THIS FILE BY HAND IS NOT RECOMMENDED                                 | -->
<!-- =================================================================================== -->
<robot name="aubo_i5" xmlns:xacro="http://ros.org/wiki/xacro">
  <!-- Defining the colors used in this robot -->
  <material name="Black">
    <color rgba="0 0 0 1"/>
  </material>
  <material name="White">
    <color rgba="1 1 1 1"/>
  </material>
  <material name="Blue">
    <color rgba="0 0 1 1"/>
  </material>
  <material name="Red">
    <color rgba="1 0 0 1"/>
  </material>
  <material name="Grey">
    <color rgba="0.96 0.96 0.96 1"/>
  </material>
  <!--/////////////////// DYNAMICS PARAM //////////////////////-->
  <!--/////////////////////////////// BASE_LINK ////////////////////////////////////-->
  <link name="base_link">
    <inertial>
      <origin rpy="0 0 0" xyz="-1.4795E-13 0.0015384 0.020951"/>
      <mass value="0.83419"/>
      <inertia ixx="0.0014414" ixy="7.8809E-15" ixz="8.5328E-16" iyy="0.0013542" iyz="-1.4364E-05" izz="0.0024659"/>
    </inertial>
    <visual>
      <origin rpy="0 0 0" xyz="0 0 0"/>
      <geometry>
        <mesh filename="package://aubo_i5/meshes/visual/base_link.DAE"/>
      </geometry>
      <material name="">
        <color rgba="1 1 1 1"/>
      </material>
    </visual>
    <collision>
      <origin rpy="0 0 0" xyz="0 0 0"/>
      <geometry>
        <mesh filename="package://aubo_i5/meshes/collision/base_link.STL"/>
      </geometry>
    </collision>
  </link>
  <!--/////////////////////////////// SHOULDER_LINK ////////////////////////////////////-->
  <link name="shoulder_Link">
    <inertial>
      <origin rpy="0 0 0" xyz="0.0 0.006 -0.002"/>
      <mass value="5.05"/>
      <inertia ixx="0.0148" ixy="0" ixz="0" iyy="0.0143" iyz="-0.0" izz="0.0095"/>
    </inertial>
    <visual>
      <origin rpy="0 0 0" xyz="0 0 0"/>
      <geometry>
        <mesh filename="package://aubo_i5/meshes/visual/shoulder_Link.DAE"/>
      </geometry>
      <material name="">
        <color rgba="1 1 1 1"/>
      </material>
    </visual>
    <collision>
      <origin rpy="0 0 0" xyz="0 0 0"/>
      <geometry>
        <mesh filename="package://aubo_i5/meshes/collision/shoulder_Link.STL"/>
      </geometry>
    </collision>
  </link>
  <!--/////////////////////////////// SHOULDER_JOINT ////////////////////////////////////-->
  <joint name="shoulder_joint" type="revolute">
    <origin rpy="0 0 3.1416" xyz="0 0 0.122"/>
    <parent link="base_link"/>
    <child link="shoulder_Link"/>
    <axis xyz="0 0 1"/>
    <limit effort="300" lower="-3.05" upper="3.05" velocity="100"/>
  </joint>
  <!--/////////////////////////////// UPPERARM_LINK ////////////////////////////////////-->
  <link name="upperArm_Link">
    <inertial>
      <origin rpy="0 0 0" xyz="0.304 0.0 -0.03"/>
      <mass value="11.90"/>
      <inertia ixx="0.0305" ixy="0" ixz="0" iyy="0.4505" iyz="0" izz="0.0095"/>
    </inertial>
    <visual>
      <origin rpy="0 0 0" xyz="0 0 0"/>
      <geometry>
        <mesh filename="package://aubo_i5/meshes/visual/upperArm_Link.DAE"/>
      </geometry>
      <material name="">
        <color rgba="1 1 1 1"/>
      </material>
    </visual>
    <collision>
      <origin rpy="0 0 0" xyz="0 0 0"/>
      <geometry>
        <mesh filename="package://aubo_i5/meshes/collision/upperArm_Link.STL"/>
      </geometry>
    </collision>
  </link>
  <!--/////////////////////////////// UPPERARM_JOINT ////////////////////////////////////-->
  <joint name="upperArm_joint" type="revolute">
    <origin rpy="-1.5708 -1.5708 0" xyz="0 0.1215 0"/>
    <parent link="shoulder_Link"/>
    <child link="upperArm_Link"/>
    <axis xyz="0 0 1"/>
    <limit effort="300" lower="-3.05" upper="3.05" velocity="100"/>
  </joint>
  <!--/////////////////////////////// FOREARM_LINK ////////////////////////////////////-->
  <link name="foreArm_Link">
    <inertial>
      <origin rpy="0 0 0" xyz="0.415 0.0 0.0992"/>
      <mass value="3.3"/>
      <inertia ixx="0.0033" ixy="0" ixz="0.0009" iyy="0.0575" iyz="0" izz="0.0565"/>
    </inertial>
    <visual>
      <origin rpy="0 0 0" xyz="0 0 0"/>
      <geometry>
        <mesh filename="package://aubo_i5/meshes/visual/foreArm_Link.DAE"/>
      </geometry>
      <material name="">
        <color rgba="1 1 1 1"/>
      </material>
    </visual>
    <collision>
      <origin rpy="0 0 0" xyz="0 0 0"/>
      <geometry>
        <mesh filename="package://aubo_i5/meshes/collision/foreArm_Link.STL"/>
      </geometry>
    </collision>
  </link>
  <!--/////////////////////////////// FOREARM_JOINT ////////////////////////////////////-->
  <joint name="foreArm_joint" type="revolute">
    <origin rpy="-3.1416 -5.1632E-18 -5.459E-16" xyz="0.408 0 0"/>
    <parent link="upperArm_Link"/>
    <child link="foreArm_Link"/>
    <axis xyz="0 0 1"/>
    <limit effort="300" lower="-3.05" upper="3.05" velocity="100"/>
  </joint>
  <!--/////////////////////////////// WRIST1_LINK ////////////////////////////////////-->
  <link name="wrist1_Link">
    <inertial>
      <origin rpy="0 0 0" xyz="0.0 0.0028 -0.003"/>
      <mass value="1.62"/>
      <inertia ixx="0.0023" ixy="0" ixz="0" iyy="0.0013" iyz="0.0" izz="0.0022"/>
    </inertial>
    <visual>
      <origin rpy="0 0 0" xyz="0 0 0"/>
      <geometry>
        <mesh filename="package://aubo_i5/meshes/visual/wrist1_Link.DAE"/>
      </geometry>
      <material name="">
        <color rgba="1 1 1 1"/>
      </material>
    </visual>
    <collision>
      <origin rpy="0 0 0" xyz="0 0 0"/>
      <geometry>
        <mesh filename="package://aubo_i5/meshes/collision/wrist1_Link.STL"/>
      </geometry>
    </collision>
  </link>
  <!--/////////////////////////////// WRIST1_JOINT ////////////////////////////////////-->
  <joint name="wrist1_joint" type="revolute">
    <origin rpy="3.1416 -1.8323E-15 1.5708" xyz="0.376 0 0"/>
    <parent link="foreArm_Link"/>
    <child link="wrist1_Link"/>
    <axis xyz="0 0 1"/>
    <limit effort="300" lower="-3.05" upper="3.05" velocity="100"/>
  </joint>
  <!--/////////////////////////////// WRIST2_LINK ////////////////////////////////////-->
  <link name="wrist2_Link">
    <inertial>
      <origin rpy="0 0 0" xyz="0.0 -0.0028 -0.003"/>
      <mass value="1.62"/>
      <inertia ixx="0.0023" ixy="0" ixz="0" iyy="0.0013" iyz="0.0" izz="0.0022"/>
    </inertial>
    <visual>
      <origin rpy="0 0 0" xyz="0 0 0"/>
      <geometry>
        <mesh filename="package://aubo_i5/meshes/visual/wrist2_Link.DAE"/>
      </geometry>
      <material name="">
        <color rgba="1 1 1 1"/>
      </material>
    </visual>
    <collision>
      <origin rpy="0 0 0" xyz="0 0 0"/>
      <geometry>
        <mesh filename="package://aubo_i5/meshes/collision/wrist2_Link.STL"/>
      </geometry>
    </collision>
  </link>
  <!--/////////////////////////////// WRIST2_JOINT ////////////////////////////////////-->
  <joint name="wrist2_joint" type="revolute">
    <origin rpy="-1.5708 -1.8709E-15 -1.6653E-16" xyz="0 0.1025 0"/>
    <parent link="wrist1_Link"/>
    <child link="wrist2_Link"/>
    <axis xyz="0 0 1"/>
    <limit effort="300" lower="-3.05" upper="3.05" velocity="100"/>
  </joint>
  <!--/////////////////////////////// WRIST3_LINK ////////////////////////////////////-->
  <link name="wrist3_Link">
    <inertial>
      <origin rpy="0 0 0" xyz="0.0 0.0 -0.0071"/>
      <mass value="0.40"/>
      <inertia ixx="0.013939" ixy="0" ixz="0" iyy="0.013988" iyz="0.0" izz="0.0224092"/>
    </inertial>
    <visual>
      <origin rpy="0 0 0" xyz="0 0 0"/>
      <geometry>
        <mesh filename="package://aubo_i5/meshes/visual/wrist3_Link.DAE"/>
      </geometry>
      <material name="">
        <color rgba="1 1 1 1"/>
      </material>
    </visual>
    <collision>
      <origin rpy="0 0 0" xyz="0 0 0"/>
      <geometry>
        <mesh filename="package://aubo_i5/meshes/collision/wrist3_Link.STL"/>
      </geometry>
    </collision>
  </link>
  <!--/////////////////////////////// WRIST3_JOINT ////////////////////////////////////-->
  <joint name="wrist3_joint" type="revolute">
    <origin rpy="1.5708 0 1.7907E-15" xyz="0 -0.094 0"/>
    <parent link="wrist2_Link"/>
    <child link="wrist3_Link"/>
    <axis xyz="0 0 1"/>
    <limit effort="300" lower="-3.05" upper="3.05" velocity="100"/>
  </joint>
  <!--////////////////////////////////// Transmissions for ROS Control //////////////////////////-->
  <transmission name="shoulder_joint_trans">
    <type>transmission_interface/SimpleTransmission</type>
    <joint name="shoulder_joint">
      <!--<hardwareInterface>hardware_interface/PositionJointInterface</hardwareInterface>-->
      <hardwareInterface>hardware_interface/PositionJointInterface</hardwareInterface>
    </joint>
    <actuator name="shoulder_joint_motor">
      <mechanicalReduction>1</mechanicalReduction>
    </actuator>
  </transmission>
  <transmission name="upperArm_joint_trans">
    <type>transmission_interface/SimpleTransmission</type>
    <joint name="upperArm_joint">
      <!--<hardwareInterface>hardware_interface/PositionJointInterface</hardwareInterface>-->
      <hardwareInterface>hardware_interface/PositionJointInterface</hardwareInterface>
    </joint>
    <actuator name="upperArm_joint_motor">
      <mechanicalReduction>1</mechanicalReduction>
    </actuator>
  </transmission>
  <transmission name="foreArm_joint_trans">
    <type>transmission_interface/SimpleTransmission</type>
    <joint name="foreArm_joint">
      <!--<hardwareInterface>hardware_interface/PositionJointInterface</hardwareInterface>-->
      <hardwareInterface>hardware_interface/PositionJointInterface</hardwareInterface>
    </joint>
    <actuator name="foreArm_joint_motor">
      <mechanicalReduction>1</mechanicalReduction>
    </actuator>
  </transmission>
  <transmission name="wrist1_joint_trans">
    <type>transmission_interface/SimpleTransmission</type>
    <joint name="wrist1_joint">
      <!--<hardwareInterface>hardware_interface/PositionJointInterface</hardwareInterface>-->
      <hardwareInterface>hardware_interface/PositionJointInterface</hardwareInterface>
    </joint>
    <actuator name="wrist1_joint_motor">
      <mechanicalReduction>1</mechanicalReduction>
    </actuator>
  </transmission>
  <transmission name="wrist2_joint_trans">
    <type>transmission_interface/SimpleTransmission</type>
    <joint name="wrist2_joint">
      <!--<hardwareInterface>hardware_interface/PositionJointInterface</hardwareInterface>-->
      <hardwareInterface>hardware_interface/PositionJointInterface</hardwareInterface>
    </joint>
    <actuator name="wrist2_joint_motor">
      <mechanicalReduction>1</mechanicalReduction>
    </actuator>
  </transmission>
  <transmission name="wrist3_joint_trans">
    <type>transmission_interface/SimpleTransmission</type>
    <joint name="wrist3_joint">
      <!--<hardwareInterface>hardware_interface/PositionJointInterface</hardwareInterface>-->
      <hardwareInterface>hardware_interface/PositionJointInterface</hardwareInterface>
    </joint>
    <actuator name="wrist3_joint_motor">
      <mechanicalReduction>1</mechanicalReduction>
    </actuator>
  </transmission>
  <!-- ros_control plugin -->
  <gazebo>
    <plugin filename="libgazebo_ros_control.so" name="gazebo_ros_control">
      <robotNamespace>/aubo_i5</robotNamespace>
    </plugin>
  </gazebo>
</robot>

