<?xml version="1.0" encoding="utf-8"?>
<!-- =================================================================================== -->
<!-- |    This document was autogenerated by xacro from robot/dobot_m1_in_world.urdf.xacro | -->
<!-- |    EDITING THIS FILE BY HAND IS NOT RECOMMENDED                                 | -->
<!-- =================================================================================== -->
<robot name="Eddie">
  <material name="Dobot/White">
    <color rgba="1 1 1 1.0"/>
  </material>
  <material name="Dobot/DarkGrey">
    <color rgba="0.3 0.3 0.3 1.0"/>
  </material>
  <material name="Dobot/LightGrey">
    <color rgba="0.8 0.8 0.8 1.0"/>
  </material>
  <material name="Dobot/Black">
    <color rgba="0 0 0 1.0"/>
  </material>
  <material name="Dobot/Grey">
    <color rgba="0.7 0.7 0.7 1.0"/>
  </material>
  <material name="Dobot/Blue">
    <color rgba="0.0 0.0 0.8 1.0"/>
  </material>
  <!-- NOTE: inertia values are approximated using meshlab and only using the significant elements -->
  <!-- from http://answers.ros.org/question/11350/is-there-any-way-to-calculate-inertial-property-of-a-robot-to-simulate-it-in-gazebo/s
    One general rule of thumb I use for checking my inertia tensors is: If total mass of the rigid body is m, and the dimension of the corresponding body is d, then check to see if ixx, iyy, izz are near m*(d/2)^2.

    This is by no means correct, but a sanity check to make sure the moment of inertia are the right order of magnitudes, so the model behaves somewhat physically realistically.
    -->
  <!-- real inertia for the head are still required -->
  <link name="world"/>
  <!-- The base fixed to its parent. -->
  <joint name="world_dobot_m1_base_joint" type="fixed">
    <origin rpy="0 0 -1.5708" xyz="0.0 0.0 0.0"/>
    <parent link="world"/>
    <child link="dobot_m1_base_link"/>
  </joint>
  <link name="dobot_m1_base_link">
    <inertial>
      <origin xyz="0 0 0"/>
      <mass value="0.2"/>
      <inertia ixx="0.02" ixy="0.0" ixz="0.0" iyy="0.02" iyz="0.0" izz="0.02"/>
    </inertial>
    <visual>
      <origin rpy="0 0 0" xyz="0 0 0"/>
      <geometry>
        <mesh filename="package://dobot_m1_description/meshes/dobot_m1_base.dae" scale="0.001 0.001 0.001"/>
      </geometry>
      <material name="Dobot/White"/>
    </visual>
    <collision>
      <origin rpy="0 0 0" xyz="0 0 0.045"/>
      <geometry>
        <cylinder length="0.09" radius="0.12"/>
      </geometry>
    </collision>
  </link>
  <!-- Stand fixed to the base -->
  <joint name="dobot_m1_stand_joint" type="fixed">
    <origin rpy="0 0 0" xyz="0 0 0"/>
    <parent link="dobot_m1_base_link"/>
    <child link="dobot_m1_stand_link"/>
  </joint>
  <link name="dobot_m1_stand_link">
    <inertial>
      <origin xyz="0 0 0"/>
      <mass value="0.2"/>
      <inertia ixx="0.02" ixy="0.0" ixz="0.0" iyy="0.02" iyz="0.0" izz="0.02"/>
    </inertial>
    <visual>
      <origin rpy="0 0 0" xyz="0 0 0"/>
      <geometry>
        <mesh filename="package://dobot_m1_description/meshes/dobot_m1_stand.dae" scale="0.001 0.001 0.001"/>
      </geometry>
      <material name="Dobot/White"/>
    </visual>
    <collision>
      <origin rpy="0 0 0" xyz="0 0 0.4"/>
      <geometry>
        <cylinder length="0.65" radius="0.09"/>
      </geometry>
    </collision>
  </link>
  <!-- Z-Axis -->
  <joint name="dobot_m1_z_axis_joint" type="prismatic">
    <origin rpy="0 0 0" xyz="0 0.1 0.097"/>
    <axis xyz="0 0 1"/>
    <limit effort="20.0" lower="0.02" upper="0.23" velocity="0.02"/>
    <dynamics damping="1.0" friction="1.0"/>
    <parent link="dobot_m1_stand_link"/>
    <child link="dobot_m1_z_axis_link"/>
  </joint>
  <link name="dobot_m1_z_axis_link">
    <inertial>
      <origin xyz="0 0 0"/>
      <mass value="0.2"/>
      <inertia ixx="0.02" ixy="0.0" ixz="0.0" iyy="0.02" iyz="0.0" izz="0.02"/>
    </inertial>
    <visual>
      <origin rpy="0 0 0" xyz="0 0 0"/>
      <geometry>
        <mesh filename="package://dobot_m1_description/meshes/dobot_m1_z-axis.dae" scale="0.001 0.001 0.001"/>
      </geometry>
      <material name="Dobot/White"/>
    </visual>
    <collision>
      <origin rpy="0 0 0" xyz="0 0 0.1"/>
      <geometry>
        <cylinder length="0.2" radius="0.07"/>
      </geometry>
    </collision>
  </link>
  <!-- 2-Axis -->
  <joint name="dobot_m1_axis_2_joint" type="revolute">
    <origin rpy="0 0 0" xyz="0 0 0"/>
    <axis xyz="0 0 1"/>
    <limit effort="204" lower="-1.4835298642" upper="1.4835298642" velocity="3.14159265359"/>
    <safety_controller k_position="30" k_velocity="30" soft_lower_limit="-1.46607657168" soft_upper_limit="1.46607657168"/>
    <dynamics damping="1.0" friction="1.0"/>
    <parent link="dobot_m1_z_axis_link"/>
    <child link="dobot_m1_axis_2_link"/>
  </joint>
  <link name="dobot_m1_axis_2_link">
    <inertial>
      <origin xyz="0 0 0"/>
      <mass value="0.2"/>
      <inertia ixx="0.02" ixy="0.0" ixz="0.0" iyy="0.02" iyz="0.0" izz="0.02"/>
    </inertial>
    <visual>
      <origin rpy="0 0 0" xyz="0 0.1 0"/>
      <geometry>
        <mesh filename="package://dobot_m1_description/meshes/dobot_m1_axis-2.dae" scale="0.001 0.001 0.001"/>
      </geometry>
      <material name="Dobot/White"/>
    </visual>
    <collision>
      <origin rpy="0 0 0" xyz="0 0 0.1"/>
      <geometry>
        <cylinder length="0.2" radius="0.07"/>
      </geometry>
    </collision>
  </link>
  <!-- 3-Axis -->
  <joint name="dobot_m1_axis_3_joint" type="revolute">
    <origin rpy="0 0 0" xyz="0 0.2 -0.05"/>
    <axis xyz="0 0 1"/>
    <limit effort="204" lower="-2.35619449019" upper="2.35619449019" velocity="3.14159265359"/>
    <safety_controller k_position="30" k_velocity="30" soft_lower_limit="-2.33874119767" soft_upper_limit="2.33874119767"/>
    <dynamics damping="1.0" friction="1.0"/>
    <parent link="dobot_m1_axis_2_link"/>
    <child link="dobot_m1_axis_3_link"/>
  </joint>
  <link name="dobot_m1_axis_3_link">
    <inertial>
      <origin xyz="0 0 0"/>
      <mass value="0.2"/>
      <inertia ixx="0.02" ixy="0.0" ixz="0.0" iyy="0.02" iyz="0.0" izz="0.02"/>
    </inertial>
    <visual>
      <origin rpy="0 0 0" xyz="0 0.1 0"/>
      <geometry>
        <mesh filename="package://dobot_m1_description/meshes/dobot_m1_axis-3.dae" scale="0.001 0.001 0.001"/>
      </geometry>
      <material name="Dobot/White"/>
    </visual>
    <collision>
      <origin rpy="0 0 0" xyz="0 0 0.1"/>
      <geometry>
        <cylinder length="0.2" radius="0.07"/>
      </geometry>
    </collision>
  </link>
  <!-- 4-Axis -->
  <joint name="dobot_m1_axis_4_joint" type="continuous">
    <origin rpy="0 0 0" xyz="0 0.2 0"/>
    <axis xyz="0 0 1"/>
    <dynamics damping="1.0" friction="1.0"/>
    <parent link="dobot_m1_axis_3_link"/>
    <child link="dobot_m1_axis_4_link"/>
  </joint>
  <link name="dobot_m1_axis_4_link">
    <inertial>
      <origin xyz="0 0 0"/>
      <mass value="0.2"/>
      <inertia ixx="0.02" ixy="0.0" ixz="0.0" iyy="0.02" iyz="0.0" izz="0.02"/>
    </inertial>
    <visual>
      <origin rpy="0 0 0" xyz="0 0 0"/>
      <geometry>
        <mesh filename="package://dobot_m1_description/meshes/dobot_m1_axis-4.dae" scale="0.001 0.001 0.001"/>
      </geometry>
      <material name="Dobot/White"/>
    </visual>
    <collision>
      <origin rpy="0 0 0" xyz="0 0 0.09"/>
      <geometry>
        <cylinder length="0.18" radius="0.07"/>
      </geometry>
    </collision>
  </link>
  <transmission name="dobot_m1_z_axis_joint_trans">
    <type>transmission_interface/SimpleTransmission</type>
    <joint name="dobot_m1_z_axis_joint">
      <hardwareInterface>PositionJointInterface</hardwareInterface>
    </joint>
    <actuator name="dobot_m1_z_axis_joint_motor">
      <mechanicalReduction>1.0</mechanicalReduction>
    </actuator>
  </transmission>
  <transmission name="dobot_m1_axis_2_joint_trans">
    <type>transmission_interface/SimpleTransmission</type>
    <joint name="dobot_m1_axis_2_joint">
      <hardwareInterface>PositionJointInterface</hardwareInterface>
    </joint>
    <actuator name="dobot_m1_axis_2_joint_motor">
      <mechanicalReduction>1.0</mechanicalReduction>
    </actuator>
  </transmission>
  <transmission name="dobot_m1_axis_3_joint_trans">
    <type>transmission_interface/SimpleTransmission</type>
    <joint name="dobot_m1_axis_3_joint">
      <hardwareInterface>PositionJointInterface</hardwareInterface>
    </joint>
    <actuator name="dobot_m1_axis_3_joint_motor">
      <mechanicalReduction>1.0</mechanicalReduction>
    </actuator>
  </transmission>
  <transmission name="dobot_m1_axis_4_joint_trans">
    <type>transmission_interface/SimpleTransmission</type>
    <joint name="dobot_m1_axis_4_joint">
      <hardwareInterface>PositionJointInterface</hardwareInterface>
    </joint>
    <actuator name="dobot_m1_axis_4_joint_motor">
      <mechanicalReduction>1.0</mechanicalReduction>
    </actuator>
  </transmission>
  <gazebo reference="dobot_m1_base_link">
    <!-- selfCollide>true</selfCollide -->
    <gravity>true</gravity>
    <mu1>500.0</mu1>
    <mu2>500.0</mu2>
    <kp>10000000.0</kp>
    <kd>1.0</kd>
    <material>Gazebo/Grey</material>
  </gazebo>
  <gazebo reference="dobot_m1_head_1_link">
    <!-- selfCollide>true</selfCollide -->
    <gravity>true</gravity>
    <mu1>500.0</mu1>
    <mu2>500.0</mu2>
    <kp>10000000.0</kp>
    <kd>1.0</kd>
    <material>Gazebo/Grey</material>
  </gazebo>
  <gazebo reference="dobot_m1_stand_link">
    <!-- selfCollide>true</selfCollide -->
    <gravity>true</gravity>
    <mu1>500.0</mu1>
    <mu2>500.0</mu2>
    <kp>10000000.0</kp>
    <kd>1.0</kd>
    <material>Gazebo/Grey</material>
  </gazebo>
  <gazebo reference="dobot_m1_z_axis_link">
    <!-- selfCollide>true</selfCollide -->
    <gravity>true</gravity>
    <mu1>500.0</mu1>
    <mu2>500.0</mu2>
    <kp>10000000.0</kp>
    <kd>1.0</kd>
    <material>Gazebo/Grey</material>
  </gazebo>
  <gazebo reference="dobot_m1_axis_2_link">
    <!-- selfCollide>true</selfCollide -->
    <gravity>true</gravity>
    <mu1>500.0</mu1>
    <mu2>500.0</mu2>
    <kp>10000000.0</kp>
    <kd>1.0</kd>
    <material>Gazebo/Grey</material>
  </gazebo>
  <gazebo reference="dobot_m1_axis_3_link">
    <!-- selfCollide>true</selfCollide -->
    <gravity>true</gravity>
    <mu1>500.0</mu1>
    <mu2>500.0</mu2>
    <kp>10000000.0</kp>
    <kd>1.0</kd>
    <material>Gazebo/Grey</material>
  </gazebo>
  <gazebo reference="dobot_m1_axis_4_link">
    <!-- selfCollide>true</selfCollide -->
    <gravity>true</gravity>
    <mu1>500.0</mu1>
    <mu2>500.0</mu2>
    <kp>10000000.0</kp>
    <kd>1.0</kd>
    <material>Gazebo/Grey</material>
  </gazebo>
  <gazebo>
    <plugin filename="libhwi_switch_gazebo_ros_control.so" name="gazebo_ros_control">
      <robotNamespace>dobot_m1</robotNamespace>
      <filterJointsParam>joints</filterJointsParam>
    </plugin>
  </gazebo>
</robot>

